 {
    "registryname": "meson_position_injector",
    "localizedname": "介子立场注入仪",
    "color": "283593",
    "parts": [
        {
            "x": -1,
            "y": 2,
            "z": 3,
            "elements": 
                "modularmachinery:blockcasing@0"
        },
        {
            "x": -1,
            "y": 0,
            "z": 0,
            "elements": "modularmachinery:blockoutputbus@2"
        },
        {
            "x": 2,
            "y": 2,
            "z": -1,
            "elements": "modularmachinery:blockcasing@0"
        },
        {
            "x": 1,
            "y": 2,
            "z": 1,
            "elements": "enderio:block_fluid_stellar_alloy@0"
        },
        {
            "x": 1,
            "y": 2,
            "z": -1,
            "elements": "modularmachinery:blockcasing@0"
        },
        {
            "x": 0,
            "y": 2,
            "z": 3,
            "elements": "modularmachinery:blockcasing@0"
        },
        {
            "x": 2,
            "y": 2,
            "z": 1,
            "elements": "modularmachinery:blockcasing@0"
        },
        {
            "x": 1,
            "y": 0,
            "z": 0,
            "elements": "modularmachinery:blockinputbus@2"
        },
        {
            "x": -1,
            "y": 0,
            "z": 2,
            "elements": "modularmachinery:blockcasing@0"
        },
        {
            "x": 0,
            "y": 0,
            "z": 2,
            "elements": "modularmachinery:blockcasing@0"
        },
        {
            "x": 0,
            "y": 2,
            "z": -1,
            "elements": "modularmachinery:blockcasing@0"
        },
        {
            "x": 1,
            "y": 2,
            "z": 3,
            "elements": "modularmachinery:blockcasing@0"
        },
        {
            "x": -1,
            "y": 2,
            "z": -1,
            "elements": "modularmachinery:blockcasing@0"
        },
        {
            "x": 2,
            "y": 2,
            "z": 3,
            "elements": "modularmachinery:blockcasing@0"
        },
        {
            "x": 1,
            "y": 0,
            "z": 2,
            "elements": "modularmachinery:blockcasing@0"
        },
        {
            "x": -2,
            "y": 2,
            "z": -1,
            "elements": "modularmachinery:blockcasing@0"
        },
        {
            "x": 1,
            "y": -1,
            "z": 0,
            "elements": "modularmachinery:blockcasing@0"
        },
        {
            "x": -2,
            "y": 1,
            "z": 0,
            "elements": "modularmachinery:blockcasing@0"
        },
        {
            "x": -1,
            "y": 3,
            "z": 1,
            "elements":"modularmachinery:blockcasing@0"
        },
        {
            "x": 0,
            "y": -1,
            "z": 0,
            "elements": "modularmachinery:blockenergyinputhatch@2"
        },
        {
            "x": -1,
            "y": 1,
            "z": 0,
            "elements": "tconevo:metal_block@2"
        },
        {
            "x": 0,
            "y": 3,
            "z": 1,
            "elements": "tconevo:metal_block@2"
        },
        {
            "x": 1,
            "y": 3,
            "z": 1,
            "elements": "modularmachinery:blockcasing@0"
        },
        {
            "x": 0,
            "y": 1,
            "z": 0,
            "elements": "tconevo:metal_block@2"
        },
        {
            "x": 2,
            "y": 1,
            "z": -1,
            "elements": "modularmachinery:blockcasing@0"
        },
        {
            "x": -1,
            "y": -1,
            "z": 0,
            "elements": "modularmachinery:blockcasing@0"
        },
        {
            "x": -2,
            "y": 1,
            "z": 2,
            "elements": "modularmachinery:blockcasing@0"
        },
        {
            "x": -1,
            "y": 1,
            "z": 2,
            "elements": "tconevo:metal_block@2"
        },
        {
            "x": 1,
            "y": 1,
            "z": 0,
            "elements": "tconevo:metal_block@2"
        },
        {
            "x": 1,
            "y": 1,
            "z": -1,
            "elements": "modularmachinery:blockcasing@0"
        },
        {
            "x": 0,
            "y": 1,
            "z": 2,
            "elements": "tconevo:metal_block@2"
        },
        {
            "x": 0,
            "y": 1,
            "z": -1,
            "elements": "modularmachinery:blockcasing@0"
        },
        {
            "x": 2,
            "y": 1,
            "z": 0,
            "elements": "modularmachinery:blockcasing@0"
        },
        {
            "x": -1,
            "y": -1,
            "z": 1,
            "elements": "modularmachinery:blockcasing@0"
        },
        {
            "x": 0,
            "y": -1,
            "z": 1,
            "elements": "modularmachinery:blockcasing@0"
        },
        {
            "x": -1,
            "y": 1,
            "z": -1,
            "elements": "modularmachinery:blockcasing@0"
        },
        {
            "x": 1,
            "y": 1,
            "z": 2,
            "elements": "tconevo:metal_block@2"
        },
        {
            "x": 2,
            "y": 1,
            "z": 2,
            "elements": "modularmachinery:blockcasing@0"
        },
        {
            "x": 1,
            "y": -1,
            "z": 1,
            "elements": "modularmachinery:blockcasing@0"
        },
        {
            "x": -2,
            "y": 1,
            "z": -1,
            "elements": "modularmachinery:blockcasing@0"
        },
        {
            "x": -2,
            "y": 2,
            "z": 0,
            "elements": "modularmachinery:blockcasing@0"
        },
        {
            "x": -1,
            "y": 2,
            "z": 0,
            "elements": "enderio:block_fluid_stellar_alloy@0"
        },
        {
            "x": 0,
            "y": 4,
            "z": 1,
            "elements": "modularmachinery:blockcasing@0"
        },
        {
            "x": 0,
            "y": 2,
            "z": 0,
            "elements": "enderio:block_fluid_stellar_alloy@0"
        },
        {
            "x": -2,
            "y": 2,
            "z": 2,
            "elements": "modularmachinery:blockcasing@0"
        },
        {
            "x": -1,
            "y": 2,
            "z": 2,
            "elements": "enderio:block_fluid_stellar_alloy@0"
        },
        {
            "x": 1,
            "y": 2,
            "z": 0,
            "elements": "enderio:block_fluid_stellar_alloy@0"
        },
        {
            "x": 0,
            "y": 2,
            "z": 2,
            "elements": "enderio:block_fluid_stellar_alloy@0"
        },
        {
            "x": 2,
            "y": 2,
            "z": 0,
            "elements": "modularmachinery:blockcasing@0"
        },
        {
            "x": -1,
            "y": 0,
            "z": 1,
            "elements": "modularmachinery:blockcasing@0"
        },
        {
            "x": 0,
            "y": 0,
            "z": 1,
            "elements": "enderio:block_fluid_stellar_alloy@0"
        },
        {
            "x": 1,
            "y": 2,
            "z": 2,
            "elements": "enderio:block_fluid_stellar_alloy@0"
        },
        {
            "x": 2,
            "y": 2,
            "z": 2,
            "elements": "modularmachinery:blockcasing@0"
        },
        {
            "x": 1,
            "y": 0,
            "z": 1,
            "elements": "modularmachinery:blockcasing@0"
        },
        {
            "x": -1,
            "y": 3,
            "z": 0,
            "elements": "modularmachinery:blockcasing@0"
        },
        {
            "x": 0,
            "y": 3,
            "z": 0,
            "elements": "modularmachinery:blockcasing@0"
        },
        {
            "x": 1,
            "y": 3,
            "z": 0,
            "elements": "modularmachinery:blockcasing@0"
        },
        {
            "x": -2,
            "y": 1,
            "z": 1,
            "elements": "modularmachinery:blockcasing@0"
        },
        {
            "x": -1,
            "y": 3,
            "z": 2,
            "elements": "modularmachinery:blockcasing@0"
        },
        {
            "x": -1,
            "y": 1,
            "z": 1,
            "elements": "tconevo:metal_block@2"
        },
        {
            "x": 0,
            "y": 3,
            "z": 2,
            "elements": "modularmachinery:blockcasing@0"
        },
        {
            "x": 1,
            "y": 3,
            "z": 2,
            "elements": "modularmachinery:blockcasing@0"
        },
        {
            "x": 0,
            "y": 1,
            "z": 1,
            "elements": "additions:future_metal-rainbow_steel_block@0"
        },
        {
            "x": -2,
            "y": 1,
            "z": 3,
            "elements": "modularmachinery:blockcasing@0"
        },
        {
            "x": -1,
            "y": 1,
            "z": 3,
            "elements": "modularmachinery:blockcasing@0"
        },
        {
            "x": 1,
            "y": 1,
            "z": 1,
            "elements": "tconevo:metal_block@2"
        },
        {
            "x": 0,
            "y": 1,
            "z": 3,
            "elements": "modularmachinery:blockcasing@0"
        },
        {
            "x": 2,
            "y": 1,
            "z": 1,
            "elements": "modularmachinery:blockcasing@0"
        },
        {
            "x": -1,
            "y": -1,
            "z": 2,
            "elements": "modularmachinery:blockcasing@0"
        },
        {
            "x": 0,
            "y": -1,
            "z": 2,
            "elements": "modularmachinery:blockcasing@0"
        },
        {
            "x": 1,
            "y": 1,
            "z": 3,
            "elements": "modularmachinery:blockcasing@0"
        },
        {
            "x": 2,
            "y": 1,
            "z": 3,
            "elements": "modularmachinery:blockcasing@0"
        },
        {
            "x": 1,
            "y": -1,
            "z": 2,
            "elements": "modularmachinery:blockcasing@0"
        },
        {
            "x": -2,
            "y": 2,
            "z": 1,
            "elements": "modularmachinery:blockcasing@0"
        },
        {
            "x": -1,
            "y": 2,
            "z": 1,
            "elements": "enderio:block_fluid_stellar_alloy@0"
        },
        {
            "x": 0,
            "y": 2,
            "z": 1,
            "elements": "enderio:block_fluid_stellar_alloy@0"
        },
        {
            "x": -2,
            "y": 2,
            "z": 3,
            "elements": "modularmachinery:blockcasing@0"
        }
    ]}