{
    "registryname": "modular_assembler",
    "localizedname": "Modular Assembler",
    "parts": [
        {
            "x": -1,
            "y": 0,
            "z": 0,
            "elements": [
                "minecraft:glass@0"
            ]
        },
        {
            "x": -2,
            "y": 0,
            "z": 2,
            "elements": [
                "minecraft:glass@0"
            ]
        },
        {
            "x": -1,
            "y": 2,
            "z": 3,
            "elements": [
                "modularmachinery:blockcasing@0"
            ]
        },
        {
            "x": 1,
            "y": 2,
            "z": 1,
            "elements": [
                "modularmachinery:blockcasing@0"
            ]
        },
        {
            "x": 1,
            "y": 0,
            "z": 0,
            "elements": [
                "minecraft:glass@0"
            ]
        },
        {
            "x": 0,
            "y": 2,
            "z": 3,
            "elements": [
                "minecraft:glass@0"
            ]
        },
        {
            "x": -1,
            "y": -2,
            "z": 1,
            "elements": [
                "modularmachinery:blockcasing@0"
            ]
        },
        {
            "x": 1,
            "y": 2,
            "z": 3,
            "elements": [
                "modularmachinery:blockcasing@0"
            ]
        },
        {
            "x": 0,
            "y": 0,
            "z": 2,
            "elements": [
                "additions:additions-blockmodularium@0"
            ]
        },
        {
            "x": -1,
            "y": 0,
            "z": 4,
            "elements": [
                "minecraft:glass@0"
            ]
        },
        {
            "x": 0,
            "y": -2,
            "z": 1,
            "elements": [
                "minecraft:glass@0"
            ]
        },
        {
            "x": 0,
            "y": 0,
            "z": 4,
            "elements": [
                "minecraft:glass@0"
            ]
        },
        {
            "x": 2,
            "y": 0,
            "z": 2,
            "elements": [
                "minecraft:glass@0"
            ]
        },
        {
            "x": 1,
            "y": -2,
            "z": 1,
            "elements": [
                "modularmachinery:blockcasing@0"
            ]
        },
        {
            "x": -1,
            "y": -2,
            "z": 3,
            "elements": [
                "modularmachinery:blockcasing@0"
            ]
        },
        {
            "x": 1,
            "y": 0,
            "z": 4,
            "elements": [
                "minecraft:glass@0"
            ]
        },
        {
            "x": 0,
            "y": -2,
            "z": 3,
            "elements": [
                "minecraft:glass@0"
            ]
        },
        {
            "x": 1,
            "y": -2,
            "z": 3,
            "elements": [
                "modularmachinery:blockcasing@0"
            ]
        },
        {
            "x": 1,
            "y": -1,
            "z": 0,
            "elements": [
                "modularmachinery:blockcasing@0",
                "modularmachinery:blockinputbus@0",
                "modularmachinery:blockinputbus@1",
                "modularmachinery:blockinputbus@2",
                "modularmachinery:blockfluidinputhatch@0",
                "modularmachinery:blockfluidinputhatch@1",
                "modularmachinery:blockfluidinputhatch@2",
                "modularmachinery:blockenergyinputhatch@0",
                "modularmachinery:blockenergyinputhatch@1",
                "modularmachinery:blockenergyinputhatch@2",
                "modularmachinery:blockoutputbus@0",
                "modularmachinery:blockoutputbus@1",
                "modularmachinery:blockoutputbus@2"
            ]
        },
        {
            "x": -1,
            "y": 1,
            "z": 0,
            "elements": [
                "modularmachinery:blockcasing@0",
                "modularmachinery:blockinputbus@0",
                "modularmachinery:blockinputbus@1",
                "modularmachinery:blockinputbus@2",
                "modularmachinery:blockfluidinputhatch@0",
                "modularmachinery:blockfluidinputhatch@1",
                "modularmachinery:blockfluidinputhatch@2",
                "modularmachinery:blockenergyinputhatch@0",
                "modularmachinery:blockenergyinputhatch@1",
                "modularmachinery:blockenergyinputhatch@2",
                "modularmachinery:blockoutputbus@0",
                "modularmachinery:blockoutputbus@1",
                "modularmachinery:blockoutputbus@2"
            ]
        },
        {
            "x": 0,
            "y": -1,
            "z": 0,
            "elements": [
                "minecraft:glass@0"
            ]
        },
        {
            "x": -1,
            "y": -1,
            "z": 0,
            "elements": [
                "modularmachinery:blockcasing@0",
                "modularmachinery:blockinputbus@0",
                "modularmachinery:blockinputbus@1",
                "modularmachinery:blockinputbus@2",
                "modularmachinery:blockfluidinputhatch@0",
                "modularmachinery:blockfluidinputhatch@1",
                "modularmachinery:blockfluidinputhatch@2",
                "modularmachinery:blockenergyinputhatch@0",
                "modularmachinery:blockenergyinputhatch@1",
                "modularmachinery:blockenergyinputhatch@2",
                "modularmachinery:blockoutputbus@0",
                "modularmachinery:blockoutputbus@1",
                "modularmachinery:blockoutputbus@2"
            ]
        },
        {
            "x": 0,
            "y": 1,
            "z": 0,
            "elements": [
                "minecraft:glass@0"
            ]
        },
        {
            "x": -2,
            "y": 1,
            "z": 2,
            "elements": [
                "minecraft:glass@0"
            ]
        },
        {
            "x": 1,
            "y": 1,
            "z": 0,
            "elements": [
                "modularmachinery:blockcasing@0",
                "modularmachinery:blockinputbus@0",
                "modularmachinery:blockinputbus@1",
                "modularmachinery:blockinputbus@2",
                "modularmachinery:blockfluidinputhatch@0",
                "modularmachinery:blockfluidinputhatch@1",
                "modularmachinery:blockfluidinputhatch@2",
                "modularmachinery:blockenergyinputhatch@0",
                "modularmachinery:blockenergyinputhatch@1",
                "modularmachinery:blockenergyinputhatch@2",
                "modularmachinery:blockoutputbus@0",
                "modularmachinery:blockoutputbus@1",
                "modularmachinery:blockoutputbus@2"
            ]
        },
        {
            "x": -2,
            "y": -1,
            "z": 1,
            "elements": [
                "modularmachinery:blockcasing@0"
            ]
        },
        {
            "x": -2,
            "y": -1,
            "z": 3,
            "elements": [
                "modularmachinery:blockcasing@0"
            ]
        },
        {
            "x": -1,
            "y": 1,
            "z": 4,
            "elements": [
                "modularmachinery:blockcasing@0"
            ]
        },
        {
            "x": 0,
            "y": 1,
            "z": 4,
            "elements": [
                "minecraft:glass@0"
            ]
        },
        {
            "x": 2,
            "y": 1,
            "z": 2,
            "elements": [
                "minecraft:glass@0"
            ]
        },
        {
            "x": 1,
            "y": 1,
            "z": 4,
            "elements": [
                "modularmachinery:blockcasing@0"
            ]
        },
        {
            "x": 2,
            "y": -1,
            "z": 1,
            "elements": [
                "modularmachinery:blockcasing@0"
            ]
        },
        {
            "x": 2,
            "y": -1,
            "z": 3,
            "elements": [
                "modularmachinery:blockcasing@0"
            ]
        },
        {
            "x": -2,
            "y": 0,
            "z": 1,
            "elements": [
                "minecraft:glass@0"
            ]
        },
        {
            "x": -1,
            "y": 2,
            "z": 2,
            "elements": [
                "minecraft:glass@0"
            ]
        },
        {
            "x": 0,
            "y": 2,
            "z": 2,
            "elements": [
                "minecraft:glass@0"
            ]
        },
        {
            "x": -2,
            "y": 0,
            "z": 3,
            "elements": [
                "minecraft:glass@0"
            ]
        },
        {
            "x": 1,
            "y": 2,
            "z": 2,
            "elements": [
                "minecraft:glass@0"
            ]
        },
        {
            "x": 2,
            "y": 0,
            "z": 1,
            "elements": [
                "minecraft:glass@0"
            ]
        },
        {
            "x": -1,
            "y": -2,
            "z": 2,
            "elements": [
                "minecraft:glass@0"
            ]
        },
        {
            "x": 0,
            "y": -2,
            "z": 2,
            "elements": [
                "minecraft:glass@0"
            ]
        },
        {
            "x": 2,
            "y": 0,
            "z": 3,
            "elements": [
                "minecraft:glass@0"
            ]
        },
        {
            "x": 1,
            "y": -2,
            "z": 2,
            "elements": [
                "minecraft:glass@0"
            ]
        },
        {
            "x": -2,
            "y": 1,
            "z": 1,
            "elements": [
                "modularmachinery:blockcasing@0"
            ]
        },
        {
            "x": -2,
            "y": 1,
            "z": 3,
            "elements": [
                "modularmachinery:blockcasing@0"
            ]
        },
        {
            "x": -2,
            "y": -1,
            "z": 2,
            "elements": [
                "minecraft:glass@0"
            ]
        },
        {
            "x": 2,
            "y": 1,
            "z": 1,
            "elements": [
                "modularmachinery:blockcasing@0"
            ]
        },
        {
            "x": -1,
            "y": -1,
            "z": 4,
            "elements": [
                "modularmachinery:blockcasing@0"
            ]
        },
        {
            "x": 2,
            "y": 1,
            "z": 3,
            "elements": [
                "modularmachinery:blockcasing@0"
            ]
        },
        {
            "x": 0,
            "y": -1,
            "z": 4,
            "elements": [
                "minecraft:glass@0"
            ]
        },
        {
            "x": 2,
            "y": -1,
            "z": 2,
            "elements": [
                "minecraft:glass@0"
            ]
        },
        {
            "x": 1,
            "y": -1,
            "z": 4,
            "elements": [
                "modularmachinery:blockcasing@0"
            ]
        },
        {
            "x": -1,
            "y": 2,
            "z": 1,
            "elements": [
                "modularmachinery:blockcasing@0"
            ]
        },
        {
            "x": 0,
            "y": 2,
            "z": 1,
            "elements": [
                "minecraft:glass@0"
            ]
        }
    ]}